Workbook

Sheet Cover
B2: Boeing–Spirit Merger Analysis: Collar Valuation and Merger Arbitrage
B3: Collar pricer · Prepared by Alessandro Radice · Educational project, not investment advice · January 2026
B6: Question | C6: On 30 June 2024 Boeing agreed to buy Spirit AeroSystems for $37.25 a share, paid in Boeing stock, with a collar. What was the offer worth to Spirit shareholders, how did it compare with the alternatives, and what did they actually receive?
B7: Inputs | C7: Deal terms from the proxy statement, Boeing and the Treasury rate on 28 June 2024 (last close before signing), and the implied volatility at the two collar strikes from the Boeing surface fitted in Python.
B8: Pricer | C8: The collar as $37.25 paid at closing, minus 0.25 puts at $149.00, plus 0.18 calls at $206.94, all Black-Scholes, plus the small Monte Carlo averaging correction from Python. Compared with a fixed exchange ratio and a fixed value with no collar. Payoff at any Boeing VWAP.
B9: Scenarios | C9: Value per Spirit share for Boeing VWAPs from $100 to $280, under the three structures.
B10: Band grid | C10: Collar value for other floors and caps (as % of Boeing at signing), at a single flat volatility.
B11: Paths | C11: Every trading day from 1 July 2024 to closing: Boeing, Spirit, the 15-day VWAP, the value if the deal had closed that day, the model value from Python, the merger-arbitrage spread and the implied probability of completion.
B12: Checks | C12: Reconciliation with the Python engine (notebook sections 5 to 9).
B13: Switches | C13: Inputs!C6 = Boeing VWAP for the payoff on the Pricer sheet; Inputs!C7 = expected closing date; Inputs!C8 = Spirit price if the deal breaks.
B14: Colour code | C14: Blue = hard-coded input · Black = formula · Green = link to another sheet · Yellow fill = switch.
B15: Where the volatility comes from | C15: Boeing's implied volatility surface is fitted every day in Python (Boeing_Spirit_Collar_Analysis.ipynb) from end-of-day option quotes. This workbook takes the vols at the collar strikes and the daily model values as inputs; every other number is a live formula.
B16: Sources | C16: Boeing option chains and Boeing and Spirit prices: DoltHub post-no-preference/options and /stocks. Treasury yields: FRED. Deal terms: Spirit DEFM14A (20 Dec 2024) and Form 8-K (8 Dec 2025).

Sheet Inputs
B2: Inputs
B3: Per Spirit share unless stated · market on Friday 28 June 2024, the last close before signing
B5: Switches
B6: Boeing VWAP for the payoff (Pricer sheet) | C6: 182.01 | D6: Try 136.59 (April 2025 low), 190.54 (actual VWAP), 237.38 (September 2025 high)
B7: Expected closing date | C7: 45838 | D7: "Mid-2025" at signing. Actual effective time: 8 December 2025
B8: Spirit price if the deal breaks | C8: 28.6 | D8: Unaffected close on 29 February 2024, before reports of talks (Spirit announcement)
B10: Deal terms | C10: Value | D10: Note / source
B11: Value per Spirit share inside the band | C11: 37.25 | D11: Merger agreement, 30 June 2024 (Spirit DEFM14A)
B12: Floor (Boeing VWAP) | C12: 149 | D12: At or below: exchange ratio fixed
B13: Cap (Boeing VWAP) | C13: 206.94 | D13: At or above: exchange ratio fixed
B14: Exchange ratio at or below the floor | C14: 0.25 | D14: Contract figure; = $37.25 / $149.00
B15: Exchange ratio at or above the cap | C15: 0.18 | D15: Contract figure; = $37.25 / $206.94
B16: Check: floor ratio − value / floor | C16: =C14-C11/C12 -> 0 | D16: Should be 0
B17: Check: cap ratio − value / cap | C17: =C15-C11/C13 -> -3.8658548e-06 | D17: Rounding in the contract: 0.18 vs 0.180004
B18: VWAP window | C18: 15 trading days | D18: Ending on the second full trading day before the effective time
B20: Market, 28 June 2024 | C20: Value | D20: Note / source
B21: Valuation date | C21: 45471 | D21: Last close before the Sunday 30 June signing
B22: Years to closing | C22: =(C7-C21)/365 -> 1.0054795 | D22: Calendar days / 365
B23: Boeing close | C23: 182.01 | D23: Sets the fixed-ratio alternative: $37.25 / close
B24: Boeing spot at the quote snapshot | C24: 182.31942 | D24: Put-call parity across near-the-money strikes (Python)
B25: Risk-free rate, continuous | C25: 0.04962713 | D25: FRED Treasury curve at the closing horizon, ln(1 + y)
B26: Dividend yield | C26: 0 | D26: Boeing dividend suspended since 2020
B27: Implied vol at the $149.00 put strike | C27: 0.3358331 | D27: Boeing SVI surface, 28 June 2024, at the closing horizon (Python, section 5)
B28: Implied vol at the $206.94 call strike | C28: 0.32030495 | D28: Same surface; the skew makes the put vol higher
B29: At-the-money implied vol | C29: 0.32204842 | D29: Used for the band grid (flat vol)
B30: Discount factor to closing | C30: =EXP(-C25*C22) -> 0.95132545
B31: Forward to closing | C31: =C24*EXP((C25-C26)*C22) -> 191.64779 | D31: F = S e^((r − q) T)
B33: Closing, 8 December 2025 | C33: Value | D33: Note / source
B34: Exchange ratio applied | C34: 0.1955 | D34: Spirit Form 8-K, 8 December 2025
B35: Boeing close on the closing day | C35: 206.27 | D35: DoltHub, 8 December 2025
B36: Implied Boeing VWAP | C36: =C11/C34 -> 190.53708 | D36: Ratio rounded to four decimals

Sheet Pricer
B2: Pricer
B3: Black-Scholes, per Spirit share · valuation 28 June 2024 · closing on Inputs!C7
B5: Option leg | C5: Strike | D5: Implied vol | E5: d1 | F5: d2 | G5: Price | H5: Quantity | I5: Value
B6: Put on Boeing (Spirit holders are short) | C6: =Inputs!C12 -> 149 | D6: =Inputs!C27 -> 0.3358331 | E6: =(LN(Inputs!$C$24/C6)+(Inputs!$C$25-Inputs!$C$26+D6^2/2)*Inputs!$C$22)/(D6*SQRT(Inputs!$C$22)) -> 0.91584884 | F6: =E6-D6*SQRT(Inputs!$C$22) -> 0.57909691 | G6: =C6*Inputs!$C$30*NORMSDIST(-F6)-Inputs!$C$24*EXP(-Inputs!$C$26*Inputs!$C$22)*NORMSDIST(-E6) -> 7.0738109 | H6: =-Inputs!C14 -> -0.25 | I6: =G6*H6 -> -1.7684527
B7: Call on Boeing (Spirit holders are long) | C7: =Inputs!C13 -> 206.94 | D7: =Inputs!C28 -> 0.32030495 | E7: =(LN(Inputs!$C$24/C7)+(Inputs!$C$25-Inputs!$C$26+D7^2/2)*Inputs!$C$22)/(D7*SQRT(Inputs!$C$22)) -> -0.078432155 | F7: =E7-D7*SQRT(Inputs!$C$22) -> -0.39961345 | G7: =Inputs!$C$24*EXP(-Inputs!$C$26*Inputs!$C$22)*NORMSDIST(E7)-C7*Inputs!$C$30*NORMSDIST(F7) -> 17.596581 | H7: =Inputs!C15 -> 0.18 | I7: =G7*H7 -> 3.1673845
B10: Value of the offer on signing day | C10: Value | D10: vs fixed ratio
B11: $37.25 paid at closing, discounted | C11: =Inputs!C11*Inputs!C30 -> 35.436873
B12: Puts sold at the floor | C12: =I6 -> -1.7684527
B13: Calls kept above the cap | C13: =I7 -> 3.1673845
B14: Averaging and delivery lag (Monte Carlo, Python) | C14: -0.001359
B15: Collar (actual terms) | C15: =SUM(C11:C14) -> 36.834446 | D15: =C15-C16 -> -0.47887912
B16: Fixed exchange ratio (= $37.25 / Boeing close) | C16: =Inputs!C11/Inputs!C23*Inputs!C24*EXP(-Inputs!C26*Inputs!C22) -> 37.313325 | D16: =C16-C16 -> 0
B17: Fixed value, no collar | C17: =C11 -> 35.436873 | D17: =C17-C16 -> -1.8764519
B18: Fixed exchange ratio used | C18: =Inputs!C11/Inputs!C23 -> 0.20465908
B19: Cost of the collar vs fixed ratio, $M on ~126.2M shares | C19: =(C16-C15)*4700/Inputs!C11 -> 60.422332
B20: Shares ≈ $4.7bn equity value / $37.25 (Boeing announcement). The averaging row is the Monte Carlo correction for the 15-day VWAP and the two-day delivery lag at the Inputs!C7 closing date (notebook section 5); −$0.0014 for a mid-2025 closing, about −$0.015 for the actual 8 December 2025 closing. Update it from the notebook if you move Inputs!C7.
B22: Payoff at the VWAP on Inputs!C6 | C22: Value
B23: Boeing VWAP | C23: =Inputs!C6 -> 182.01
B24: Regime | C24: =IF(C23<=Inputs!C12,"Below the band",IF(C23>=Inputs!C13,"Above the band","Inside the band")) -> Inside the band
B25: Boeing shares per Spirit share | C25: =IF(C23<=Inputs!C12,Inputs!C14,IF(C23>=Inputs!C13,Inputs!C15,Inputs!C11/C23)) -> 0.20465908
B26: Collar value per Spirit share | C26: =C25*C23 -> 37.25
B27: Fixed exchange ratio | C27: =C18*C23 -> 37.25
B28: Fixed value, no collar | C28: =Inputs!C11 -> 37.25
B29: Collar vs fixed ratio | C29: =C26-C27 -> 0

Sheet Scenarios
B2: Scenarios
B3: Value per Spirit share at closing, by Boeing VWAP (shares valued at the VWAP)
B5: Boeing VWAP | C5: Regime | D5: Ratio | E5: Collar | F5: Fixed ratio | G5: Fixed value | H5: Collar − fixed ratio
B6: 100 | C6: =IF(B6<=Inputs!$C$12,"Below",IF(B6>=Inputs!$C$13,"Above","Inside")) -> Below | D6: =IF(B6<=Inputs!$C$12,Inputs!$C$14,IF(B6>=Inputs!$C$13,Inputs!$C$15,Inputs!$C$11/B6)) -> 0.25 | E6: =D6*B6 -> 25 | F6: =Pricer!$C$18*B6 -> 20.465908 | G6: =Inputs!$C$11 -> 37.25 | H6: =E6-F6 -> 4.5340915
B7: 105 | C7: =IF(B7<=Inputs!$C$12,"Below",IF(B7>=Inputs!$C$13,"Above","Inside")) -> Below | D7: =IF(B7<=Inputs!$C$12,Inputs!$C$14,IF(B7>=Inputs!$C$13,Inputs!$C$15,Inputs!$C$11/B7)) -> 0.25 | E7: =D7*B7 -> 26.25 | F7: =Pricer!$C$18*B7 -> 21.489204 | G7: =Inputs!$C$11 -> 37.25 | H7: =E7-F7 -> 4.7607961
B8: 110 | C8: =IF(B8<=Inputs!$C$12,"Below",IF(B8>=Inputs!$C$13,"Above","Inside")) -> Below | D8: =IF(B8<=Inputs!$C$12,Inputs!$C$14,IF(B8>=Inputs!$C$13,Inputs!$C$15,Inputs!$C$11/B8)) -> 0.25 | E8: =D8*B8 -> 27.5 | F8: =Pricer!$C$18*B8 -> 22.512499 | G8: =Inputs!$C$11 -> 37.25 | H8: =E8-F8 -> 4.9875007
B9: 115 | C9: =IF(B9<=Inputs!$C$12,"Below",IF(B9>=Inputs!$C$13,"Above","Inside")) -> Below | D9: =IF(B9<=Inputs!$C$12,Inputs!$C$14,IF(B9>=Inputs!$C$13,Inputs!$C$15,Inputs!$C$11/B9)) -> 0.25 | E9: =D9*B9 -> 28.75 | F9: =Pricer!$C$18*B9 -> 23.535795 | G9: =Inputs!$C$11 -> 37.25 | H9: =E9-F9 -> 5.2142053
B10: 120 | C10: =IF(B10<=Inputs!$C$12,"Below",IF(B10>=Inputs!$C$13,"Above","Inside")) -> Below | D10: =IF(B10<=Inputs!$C$12,Inputs!$C$14,IF(B10>=Inputs!$C$13,Inputs!$C$15,Inputs!$C$11/B10)) -> 0.25 | E10: =D10*B10 -> 30 | F10: =Pricer!$C$18*B10 -> 24.55909 | G10: =Inputs!$C$11 -> 37.25 | H10: =E10-F10 -> 5.4409098
B11: 125 | C11: =IF(B11<=Inputs!$C$12,"Below",IF(B11>=Inputs!$C$13,"Above","Inside")) -> Below | D11: =IF(B11<=Inputs!$C$12,Inputs!$C$14,IF(B11>=Inputs!$C$13,Inputs!$C$15,Inputs!$C$11/B11)) -> 0.25 | E11: =D11*B11 -> 31.25 | F11: =Pricer!$C$18*B11 -> 25.582386 | G11: =Inputs!$C$11 -> 37.25 | H11: =E11-F11 -> 5.6676144
B12: 130 | C12: =IF(B12<=Inputs!$C$12,"Below",IF(B12>=Inputs!$C$13,"Above","Inside")) -> Below | D12: =IF(B12<=Inputs!$C$12,Inputs!$C$14,IF(B12>=Inputs!$C$13,Inputs!$C$15,Inputs!$C$11/B12)) -> 0.25 | E12: =D12*B12 -> 32.5 | F12: =Pricer!$C$18*B12 -> 26.605681 | G12: =Inputs!$C$11 -> 37.25 | H12: =E12-F12 -> 5.894319
B13: 135 | C13: =IF(B13<=Inputs!$C$12,"Below",IF(B13>=Inputs!$C$13,"Above","Inside")) -> Below | D13: =IF(B13<=Inputs!$C$12,Inputs!$C$14,IF(B13>=Inputs!$C$13,Inputs!$C$15,Inputs!$C$11/B13)) -> 0.25 | E13: =D13*B13 -> 33.75 | F13: =Pricer!$C$18*B13 -> 27.628976 | G13: =Inputs!$C$11 -> 37.25 | H13: =E13-F13 -> 6.1210236
B14: 140 | C14: =IF(B14<=Inputs!$C$12,"Below",IF(B14>=Inputs!$C$13,"Above","Inside")) -> Below | D14: =IF(B14<=Inputs!$C$12,Inputs!$C$14,IF(B14>=Inputs!$C$13,Inputs!$C$15,Inputs!$C$11/B14)) -> 0.25 | E14: =D14*B14 -> 35 | F14: =Pricer!$C$18*B14 -> 28.652272 | G14: =Inputs!$C$11 -> 37.25 | H14: =E14-F14 -> 6.3477281
B15: 145 | C15: =IF(B15<=Inputs!$C$12,"Below",IF(B15>=Inputs!$C$13,"Above","Inside")) -> Below | D15: =IF(B15<=Inputs!$C$12,Inputs!$C$14,IF(B15>=Inputs!$C$13,Inputs!$C$15,Inputs!$C$11/B15)) -> 0.25 | E15: =D15*B15 -> 36.25 | F15: =Pricer!$C$18*B15 -> 29.675567 | G15: =Inputs!$C$11 -> 37.25 | H15: =E15-F15 -> 6.5744327
B16: 150 | C16: =IF(B16<=Inputs!$C$12,"Below",IF(B16>=Inputs!$C$13,"Above","Inside")) -> Inside | D16: =IF(B16<=Inputs!$C$12,Inputs!$C$14,IF(B16>=Inputs!$C$13,Inputs!$C$15,Inputs!$C$11/B16)) -> 0.24833333 | E16: =D16*B16 -> 37.25 | F16: =Pricer!$C$18*B16 -> 30.698863 | G16: =Inputs!$C$11 -> 37.25 | H16: =E16-F16 -> 6.5511373
B17: 155 | C17: =IF(B17<=Inputs!$C$12,"Below",IF(B17>=Inputs!$C$13,"Above","Inside")) -> Inside | D17: =IF(B17<=Inputs!$C$12,Inputs!$C$14,IF(B17>=Inputs!$C$13,Inputs!$C$15,Inputs!$C$11/B17)) -> 0.24032258 | E17: =D17*B17 -> 37.25 | F17: =Pricer!$C$18*B17 -> 31.722158 | G17: =Inputs!$C$11 -> 37.25 | H17: =E17-F17 -> 5.5278419
... B42: 280 | C42: =IF(B42<=Inputs!$C$12,"Below",IF(B42>=Inputs!$C$13,"Above","Inside")) -> Above | D42: =IF(B42<=Inputs!$C$12,Inputs!$C$14,IF(B42>=Inputs!$C$13,Inputs!$C$15,Inputs!$C$11/B42)) -> 0.18 | E42: =D42*B42 -> 50.4 | F42: =Pricer!$C$18*B42 -> 57.304544 | G42: =Inputs!$C$11 -> 37.25 | H42: =E42-F42 -> -6.9045437

Sheet Band grid
B2: Band grid
B3: Collar value per Spirit share on signing day, for other floors and caps · flat vol = Inputs!C29 · the $37.25 value is kept inside the band
B5: Floor ↓ / Cap → | C5: 1 | D5: 1.025 | E5: 1.05 | F5: 1.075 | G5: 1.1 | H5: 1.125 | I5: 1.15 | J5: 1.175 | K5: 1.2 | L5: 1.225 | M5: 1.25 | N5: 1.275 | O5: 1.3
B6: 0.7 | C6: =Inputs!$C$11*Inputs!$C$30-Inputs!$C$11/($B6*Inputs!$C$23)*(($B6*Inputs!$C$23)*Inputs!$C$30*NORMSDIST(-(((LN(Inputs!$C$24/($B6*Inputs!$C$23))+(Inputs!$C$25+Inputs!$C$29^2/2)*Inputs!$C$22)/(Inputs!$C$29*SQRT(Inputs!$C$22)))-Inputs!$C$29*SQRT(Inputs!$C$22)))-Inputs!$C$24*NORMSDIST(-((LN(Inputs!$C$24/($B6*Inputs!$C$23))+(Inputs!$C$25+Inputs!$C$29^2/2)*Inputs!$C$22)/(Inputs!$C$29*SQRT(Inputs!$C$22)))))+Inputs!$C$11/(C$5*Inputs!$C$23)*(Inputs!$C$24*NORMSDIST(((LN(Inputs!$C$24/(C$5*Inputs!$C$23))+(Inputs!$C$25+Inputs!$C$29^2/2)*Inputs!$C$22)/(Inputs!$C$29*SQRT(Inputs!$C$22))))-(C$5*Inputs!$C$23)*Inputs!$C$30*NORMSDIST(((LN(Inputs!$C$24/(C$5*Inputs!$C$23))+(Inputs!$C$25+Inputs!$C$29^2/2)*Inputs!$C$22)/(Inputs!$C$29*SQRT(Inputs!$C$22)))-Inputs!$C$29*SQRT(Inputs!$C$22))) -> 40.416971 | D6: =Inputs!$C$11*Inputs!$C$30-Inputs!$C$11/($B6*Inputs!$C$23)*(($B6*Inputs!$C$23)*Inputs!$C$30*NORMSDIST(-(((LN(Inputs!$C$24/($B6*Inputs!$C$23))+(Inputs!$C$25+Inputs!$C$29^2/2)*Inputs!$C$22)/(Inputs!$C$29*SQRT(Inputs!$C$22)))-Inputs!$C$29*SQRT(Inputs!$C$22)))-Inputs!$C$24*NORMSDIST(-((LN(Inputs!$C$24/($B6*Inputs!$C$23))+(Inputs!$C$25+Inputs!$C$29^2/2)*Inputs!$C$22)/(Inputs!$C$29*SQRT(Inputs!$C$22)))))+Inputs!$C$11/(D$5*Inputs!$C$23)*(Inputs!$C$24*NORMSDIST(((LN(Inputs!$C$24/(D$5*Inputs!$C$23))+(Inputs!$C$25+Inputs!$C$29^2/2)*Inputs!$C$22)/(Inputs!$C$29*SQRT(Inputs!$C$22))))-(D$5*Inputs!$C$23)*Inputs!$C$30*NORMSDIST(((LN(Inputs!$C$24/(D$5*Inputs!$C$23))+(Inputs!$C$25+Inputs!$C$29^2/2)*Inputs!$C$22)/(Inputs!$C$29*SQRT(Inputs!$C$22)))-Inputs!$C$29*SQRT(Inputs!$C$22))) -> 39.860501 | E6: =Inputs!$C$11*Inputs!$C$30-Inputs!$C$11/($B6*Inputs!$C$23)*(($B6*Inputs!$C$23)*Inputs!$C$30*NORMSDIST(-(((LN(Inputs!$C$24/($B6*Inputs!$C$23))+(Inputs!$C$25+Inputs!$C$29^2/2)*Inputs!$C$22)/(Inputs!$C$29*SQRT(Inputs!$C$22)))-Inputs!$C$29*SQRT(Inputs!$C$22)))-Inputs!$C$24*NORMSDIST(-((LN(Inputs!$C$24/($B6*Inputs!$C$23))+(Inputs!$C$25+Inputs!$C$29^2/2)*Inputs!$C$22)/(Inputs!$C$29*SQRT(Inputs!$C$22)))))+Inputs!$C$11/(E$5*Inputs!$C$23)*(Inputs!$C$24*NORMSDIST(((LN(Inputs!$C$24/(E$5*Inputs!$C$23))+(Inputs!$C$25+Inputs!$C$29^2/2)*Inputs!$C$22)/(Inputs!$C$29*SQRT(Inputs!$C$22))))-(E$5*Inputs!$C$23)*Inputs!$C$30*NORMSDIST(((LN(Inputs!$C$24/(E$5*Inputs!$C$23))+(Inputs!$C$25+Inputs!$C$29^2/2)*Inputs!$C$22)/(Inputs!$C$29*SQRT(Inputs!$C$22)))-Inputs!$C$29*SQRT(Inputs!$C$22))) -> 39.355868 | F6: =Inputs!$C$11*Inputs!$C$30-Inputs!$C$11/($B6*Inputs!$C$23)*(($B6*Inputs!$C$23)*Inputs!$C$30*NORMSDIST(-(((LN(Inputs!$C$24/($B6*Inputs!$C$23))+(Inputs!$C$25+Inputs!$C$29^2/2)*Inputs!$C$22)/(Inputs!$C$29*SQRT(Inputs!$C$22)))-Inputs!$C$29*SQRT(Inputs!$C$22)))-Inputs!$C$24*NORMSDIST(-((LN(Inputs!$C$24/($B6*Inputs!$C$23))+(Inputs!$C$25+Inputs!$C$29^2/2)*Inputs!$C$22)/(Inputs!$C$29*SQRT(Inputs!$C$22)))))+Inputs!$C$11/(F$5*Inputs!$C$23)*(Inputs!$C$24*NORMSDIST(((LN(Inputs!$C$24/(F$5*Inputs!$C$23))+(Inputs!$C$25+Inputs!$C$29^2/2)*Inputs!$C$22)/(Inputs!$C$29*SQRT(Inputs!$C$22))))-(F$5*Inputs!$C$23)*Inputs!$C$30*NORMSDIST(((LN(Inputs!$C$24/(F$5*Inputs!$C$23))+(Inputs!$C$25+Inputs!$C$29^2/2)*Inputs!$C$22)/(Inputs!$C$29*SQRT(Inputs!$C$22)))-Inputs!$C$29*SQRT(Inputs!$C$22))) -> 38.898657 | G6: =Inputs!$C$11*Inputs!$C$30-Inputs!$C$11/($B6*Inputs!$C$23)*(($B6*Inputs!$C$23)*Inputs!$C$30*NORMSDIST(-(((LN(Inputs!$C$24/($B6*Inputs!$C$23))+(Inputs!$C$25+Inputs!$C$29^2/2)*Inputs!$C$22)/(Inputs!$C$29*SQRT(Inputs!$C$22)))-Inputs!$C$29*SQRT(Inputs!$C$22)))-Inputs!$C$24*NORMSDIST(-((LN(Inputs!$C$24/($B6*Inputs!$C$23))+(Inputs!$C$25+Inputs!$C$29^2/2)*Inputs!$C$22)/(Inputs!$C$29*SQRT(Inputs!$C$22)))))+Inputs!$C$11/(G$5*Inputs!$C$23)*(Inputs!$C$24*NORMSDIST(((LN(Inputs!$C$24/(G$5*Inputs!$C$23))+(Inputs!$C$25+Inputs!$C$29^2/2)*Inputs!$C$22)/(Inputs!$C$29*SQRT(Inputs!$C$22))))-(G$5*Inputs!$C$23)*Inputs!$C$30*NORMSDIST(((LN(Inputs!$C$24/(G$5*Inputs!$C$23))+(Inputs!$C$25+Inputs!$C$29^2/2)*Inputs!$C$22)/(Inputs!$C$29*SQRT(Inputs!$C$22)))-Inputs!$C$29*SQRT(Inputs!$C$22))) -> 38.484781 | H6: =Inputs!$C$11*Inputs!$C$30-Inputs!$C$11/($B6*Inputs!$C$23)*(($B6*Inputs!$C$23)*Inputs!$C$30*NORMSDIST(-(((LN(Inputs!$C$24/($B6*Inputs!$C$23))+(Inputs!$C$25+Inputs!$C$29^2/2)*Inputs!$C$22)/(Inputs!$C$29*SQRT(Inputs!$C$22)))-Inputs!$C$29*SQRT(Inputs!$C$22)))-Inputs!$C$24*NORMSDIST(-((LN(Inputs!$C$24/($B6*Inputs!$C$23))+(Inputs!$C$25+Inputs!$C$29^2/2)*Inputs!$C$22)/(Inputs!$C$29*SQRT(Inputs!$C$22)))))+Inputs!$C$11/(H$5*Inputs!$C$23)*(Inputs!$C$24*NORMSDIST(((LN(Inputs!$C$24/(H$5*Inputs!$C$23))+(Inputs!$C$25+Inputs!$C$29^2/2)*Inputs!$C$22)/(Inputs!$C$29*SQRT(Inputs!$C$22))))-(H$5*Inputs!$C$23)*Inputs!$C$30*NORMSDIST(((LN(Inputs!$C$24/(H$5*Inputs!$C$23))+(Inputs!$C$25+Inputs!$C$29^2/2)*Inputs!$C$22)/(Inputs!$C$29*SQRT(Inputs!$C$22)))-Inputs!$C$29*SQRT(Inputs!$C$22))) -> 38.110454 | I6: =Inputs!$C$11*Inputs!$C$30-Inputs!$C$11/($B6*Inputs!$C$23)*(($B6*Inputs!$C$23)*Inputs!$C$30*NORMSDIST(-(((LN(Inputs!$C$24/($B6*Inputs!$C$23))+(Inputs!$C$25+Inputs!$C$29^2/2)*Inputs!$C$22)/(Inputs!$C$29*SQRT(Inputs!$C$22)))-Inputs!$C$29*SQRT(Inputs!$C$22)))-Inputs!$C$24*NORMSDIST(-((LN(Inputs!$C$24/($B6*Inputs!$C$23))+(Inputs!$C$25+Inputs!$C$29^2/2)*Inputs!$C$22)/(Inputs!$C$29*SQRT(Inputs!$C$22)))))+Inputs!$C$11/(I$5*Inputs!$C$23)*(Inputs!$C$24*NORMSDIST(((LN(Inputs!$C$24/(I$5*Inputs!$C$23))+(Inputs!$C$25+Inputs!$C$29^2/2)*Inputs!$C$22)/(Inputs!$C$29*SQRT(Inputs!$C$22))))-(I$5*Inputs!$C$23)*Inputs!$C$30*NORMSDIST(((LN(Inputs!$C$24/(I$5*Inputs!$C$23))+(Inputs!$C$25+Inputs!$C$29^2/2)*Inputs!$C$22)/(Inputs!$C$29*SQRT(Inputs!$C$22)))-Inputs!$C$29*SQRT(Inputs!$C$22))) -> 37.772174 | J6: =Inputs!$C$11*Inputs!$C$30-Inputs!$C$11/($B6*Inputs!$C$23)*(($B6*Inputs!$C$23)*Inputs!$C$30*NORMSDIST(-(((LN(Inputs!$C$24/($B6*Inputs!$C$23))+(Inputs!$C$25+Inputs!$C$29^2/2)*Inputs!$C$22)/(Inputs!$C$29*SQRT(Inputs!$C$22)))-Inputs!$C$29*SQRT(Inputs!$C$22)))-Inputs!$C$24*NORMSDIST(-((LN(Inputs!$C$24/($B6*Inputs!$C$23))+(Inputs!$C$25+Inputs!$C$29^2/2)*Inputs!$C$22)/(Inputs!$C$29*SQRT(Inputs!$C$22)))))+Inputs!$C$11/(J$5*Inputs!$C$23)*(Inputs!$C$24*NORMSDIST(((LN(Inputs!$C$24/(J$5*Inputs!$C$23))+(Inputs!$C$25+Inputs!$C$29^2/2)*Inputs!$C$22)/(Inputs!$C$29*SQRT(Inputs!$C$22))))-(J$5*Inputs!$C$23)*Inputs!$C$30*NORMSDIST(((LN(Inputs!$C$24/(J$5*Inputs!$C$23))+(Inputs!$C$25+Inputs!$C$29^2/2)*Inputs!$C$22)/(Inputs!$C$29*SQRT(Inputs!$C$22)))-Inputs!$C$29*SQRT(Inputs!$C$22))) -> 37.466714 | ... O6: =Inputs!$C$11*Inputs!$C$30-Inputs!$C$11/($B6*Inputs!$C$23)*(($B6*Inputs!$C$23)*Inputs!$C$30*NORMSDIST(-(((LN(Inputs!$C$24/($B6*Inputs!$C$23))+(Inputs!$C$25+Inputs!$C$29^2/2)*Inputs!$C$22)/(Inputs!$C$29*SQRT(Inputs!$C$22)))-Inputs!$C$29*SQRT(Inputs!$C$22)))-Inputs!$C$24*NORMSDIST(-((LN(Inputs!$C$24/($B6*Inputs!$C$23))+(Inputs!$C$25+Inputs!$C$29^2/2)*Inputs!$C$22)/(Inputs!$C$29*SQRT(Inputs!$C$22)))))+Inputs!$C$11/(O$5*Inputs!$C$23)*(Inputs!$C$24*NORMSDIST(((LN(Inputs!$C$24/(O$5*Inputs!$C$23))+(Inputs!$C$25+Inputs!$C$29^2/2)*Inputs!$C$22)/(Inputs!$C$29*SQRT(Inputs!$C$22))))-(O$5*Inputs!$C$23)*Inputs!$C$30*NORMSDIST(((LN(Inputs!$C$24/(O$5*Inputs!$C$23))+(Inputs!$C$25+Inputs!$C$29^2/2)*Inputs!$C$22)/(Inputs!$C$29*SQRT(Inputs!$C$22)))-Inputs!$C$29*SQRT(Inputs!$C$22))) -> 36.335585
B7: 0.725 | C7: =Inputs!$C$11*Inputs!$C$30-Inputs!$C$11/($B7*Inputs!$C$23)*(($B7*Inputs!$C$23)*Inputs!$C$30*NORMSDIST(-(((LN(Inputs!$C$24/($B7*Inputs!$C$23))+(Inputs!$C$25+Inputs!$C$29^2/2)*Inputs!$C$22)/(Inputs!$C$29*SQRT(Inputs!$C$22)))-Inputs!$C$29*SQRT(Inputs!$C$22)))-Inputs!$C$24*NORMSDIST(-((LN(Inputs!$C$24/($B7*Inputs!$C$23))+(Inputs!$C$25+Inputs!$C$29^2/2)*Inputs!$C$22)/(Inputs!$C$29*SQRT(Inputs!$C$22)))))+Inputs!$C$11/(C$5*Inputs!$C$23)*(Inputs!$C$24*NORMSDIST(((LN(Inputs!$C$24/(C$5*Inputs!$C$23))+(Inputs!$C$25+Inputs!$C$29^2/2)*Inputs!$C$22)/(Inputs!$C$29*SQRT(Inputs!$C$22))))-(C$5*Inputs!$C$23)*Inputs!$C$30*NORMSDIST(((LN(Inputs!$C$24/(C$5*Inputs!$C$23))+(Inputs!$C$25+Inputs!$C$29^2/2)*Inputs!$C$22)/(Inputs!$C$29*SQRT(Inputs!$C$22)))-Inputs!$C$29*SQRT(Inputs!$C$22))) -> 40.260403 | D7: =Inputs!$C$11*Inputs!$C$30-Inputs!$C$11/($B7*Inputs!$C$23)*(($B7*Inputs!$C$23)*Inputs!$C$30*NORMSDIST(-(((LN(Inputs!$C$24/($B7*Inputs!$C$23))+(Inputs!$C$25+Inputs!$C$29^2/2)*Inputs!$C$22)/(Inputs!$C$29*SQRT(Inputs!$C$22)))-Inputs!$C$29*SQRT(Inputs!$C$22)))-Inputs!$C$24*NORMSDIST(-((LN(Inputs!$C$24/($B7*Inputs!$C$23))+(Inputs!$C$25+Inputs!$C$29^2/2)*Inputs!$C$22)/(Inputs!$C$29*SQRT(Inputs!$C$22)))))+Inputs!$C$11/(D$5*Inputs!$C$23)*(Inputs!$C$24*NORMSDIST(((LN(Inputs!$C$24/(D$5*Inputs!$C$23))+(Inputs!$C$25+Inputs!$C$29^2/2)*Inputs!$C$22)/(Inputs!$C$29*SQRT(Inputs!$C$22))))-(D$5*Inputs!$C$23)*Inputs!$C$30*NORMSDIST(((LN(Inputs!$C$24/(D$5*Inputs!$C$23))+(Inputs!$C$25+Inputs!$C$29^2/2)*Inputs!$C$22)/(Inputs!$C$29*SQRT(Inputs!$C$22)))-Inputs!$C$29*SQRT(Inputs!$C$22))) -> 39.703934 | E7: =Inputs!$C$11*Inputs!$C$30-Inputs!$C$11/($B7*Inputs!$C$23)*(($B7*Inputs!$C$23)*Inputs!$C$30*NORMSDIST(-(((LN(Inputs!$C$24/($B7*Inputs!$C$23))+(Inputs!$C$25+Inputs!$C$29^2/2)*Inputs!$C$22)/(Inputs!$C$29*SQRT(Inputs!$C$22)))-Inputs!$C$29*SQRT(Inputs!$C$22)))-Inputs!$C$24*NORMSDIST(-((LN(Inputs!$C$24/($B7*Inputs!$C$23))+(Inputs!$C$25+Inputs!$C$29^2/2)*Inputs!$C$22)/(Inputs!$C$29*SQRT(Inputs!$C$22)))))+Inputs!$C$11/(E$5*Inputs!$C$23)*(Inputs!$C$24*NORMSDIST(((LN(Inputs!$C$24/(E$5*Inputs!$C$23))+(Inputs!$C$25+Inputs!$C$29^2/2)*Inputs!$C$22)/(Inputs!$C$29*SQRT(Inputs!$C$22))))-(E$5*Inputs!$C$23)*Inputs!$C$30*NORMSDIST(((LN(Inputs!$C$24/(E$5*Inputs!$C$23))+(Inputs!$C$25+Inputs!$C$29^2/2)*Inputs!$C$22)/(Inputs!$C$29*SQRT(Inputs!$C$22)))-Inputs!$C$29*SQRT(Inputs!$C$22))) -> 39.1993 | F7: =Inputs!$C$11*Inputs!$C$30-Inputs!$C$11/($B7*Inputs!$C$23)*(($B7*Inputs!$C$23)*Inputs!$C$30*NORMSDIST(-(((LN(Inputs!$C$24/($B7*Inputs!$C$23))+(Inputs!$C$25+Inputs!$C$29^2/2)*Inputs!$C$22)/(Inputs!$C$29*SQRT(Inputs!$C$22)))-Inputs!$C$29*SQRT(Inputs!$C$22)))-Inputs!$C$24*NORMSDIST(-((LN(Inputs!$C$24/($B7*Inputs!$C$23))+(Inputs!$C$25+Inputs!$C$29^2/2)*Inputs!$C$22)/(Inputs!$C$29*SQRT(Inputs!$C$22)))))+Inputs!$C$11/(F$5*Inputs!$C$23)*(Inputs!$C$24*NORMSDIST(((LN(Inputs!$C$24/(F$5*Inputs!$C$23))+(Inputs!$C$25+Inputs!$C$29^2/2)*Inputs!$C$22)/(Inputs!$C$29*SQRT(Inputs!$C$22))))-(F$5*Inputs!$C$23)*Inputs!$C$30*NORMSDIST(((LN(Inputs!$C$24/(F$5*Inputs!$C$23))+(Inputs!$C$25+Inputs!$C$29^2/2)*Inputs!$C$22)/(Inputs!$C$29*SQRT(Inputs!$C$22)))-Inputs!$C$29*SQRT(Inputs!$C$22))) -> 38.74209 | G7: =Inputs!$C$11*Inputs!$C$30-Inputs!$C$11/($B7*Inputs!$C$23)*(($B7*Inputs!$C$23)*Inputs!$C$30*NORMSDIST(-(((LN(Inputs!$C$24/($B7*Inputs!$C$23))+(Inputs!$C$25+Inputs!$C$29^2/2)*Inputs!$C$22)/(Inputs!$C$29*SQRT(Inputs!$C$22)))-Inputs!$C$29*SQRT(Inputs!$C$22)))-Inputs!$C$24*NORMSDIST(-((LN(Inputs!$C$24/($B7*Inputs!$C$23))+(Inputs!$C$25+Inputs!$C$29^2/2)*Inputs!$C$22)/(Inputs!$C$29*SQRT(Inputs!$C$22)))))+Inputs!$C$11/(G$5*Inputs!$C$23)*(Inputs!$C$24*NORMSDIST(((LN(Inputs!$C$24/(G$5*Inputs!$C$23))+(Inputs!$C$25+Inputs!$C$29^2/2)*Inputs!$C$22)/(Inputs!$C$29*SQRT(Inputs!$C$22))))-(G$5*Inputs!$C$23)*Inputs!$C$30*NORMSDIST(((LN(Inputs!$C$24/(G$5*Inputs!$C$23))+(Inputs!$C$25+Inputs!$C$29^2/2)*Inputs!$C$22)/(Inputs!$C$29*SQRT(Inputs!$C$22)))-Inputs!$C$29*SQRT(Inputs!$C$22))) -> 38.328214 | H7: =Inputs!$C$11*Inputs!$C$30-Inputs!$C$11/($B7*Inputs!$C$23)*(($B7*Inputs!$C$23)*Inputs!$C$30*NORMSDIST(-(((LN(Inputs!$C$24/($B7*Inputs!$C$23))+(Inputs!$C$25+Inputs!$C$29^2/2)*Inputs!$C$22)/(Inputs!$C$29*SQRT(Inputs!$C$22)))-Inputs!$C$29*SQRT(Inputs!$C$22)))-Inputs!$C$24*NORMSDIST(-((LN(Inputs!$C$24/($B7*Inputs!$C$23))+(Inputs!$C$25+Inputs!$C$29^2/2)*Inputs!$C$22)/(Inputs!$C$29*SQRT(Inputs!$C$22)))))+Inputs!$C$11/(H$5*Inputs!$C$23)*(Inputs!$C$24*NORMSDIST(((LN(Inputs!$C$24/(H$5*Inputs!$C$23))+(Inputs!$C$25+Inputs!$C$29^2/2)*Inputs!$C$22)/(Inputs!$C$29*SQRT(Inputs!$C$22))))-(H$5*Inputs!$C$23)*Inputs!$C$30*NORMSDIST(((LN(Inputs!$C$24/(H$5*Inputs!$C$23))+(Inputs!$C$25+Inputs!$C$29^2/2)*Inputs!$C$22)/(Inputs!$C$29*SQRT(Inputs!$C$22)))-Inputs!$C$29*SQRT(Inputs!$C$22))) -> 37.953886 | I7: =Inputs!$C$11*Inputs!$C$30-Inputs!$C$11/($B7*Inputs!$C$23)*(($B7*Inputs!$C$23)*Inputs!$C$30*NORMSDIST(-(((LN(Inputs!$C$24/($B7*Inputs!$C$23))+(Inputs!$C$25+Inputs!$C$29^2/2)*Inputs!$C$22)/(Inputs!$C$29*SQRT(Inputs!$C$22)))-Inputs!$C$29*SQRT(Inputs!$C$22)))-Inputs!$C$24*NORMSDIST(-((LN(Inputs!$C$24/($B7*Inputs!$C$23))+(Inputs!$C$25+Inputs!$C$29^2/2)*Inputs!$C$22)/(Inputs!$C$29*SQRT(Inputs!$C$22)))))+Inputs!$C$11/(I$5*Inputs!$C$23)*(Inputs!$C$24*NORMSDIST(((LN(Inputs!$C$24/(I$5*Inputs!$C$23))+(Inputs!$C$25+Inputs!$C$29^2/2)*Inputs!$C$22)/(Inputs!$C$29*SQRT(Inputs!$C$22))))-(I$5*Inputs!$C$23)*Inputs!$C$30*NORMSDIST(((LN(Inputs!$C$24/(I$5*Inputs!$C$23))+(Inputs!$C$25+Inputs!$C$29^2/2)*Inputs!$C$22)/(Inputs!$C$29*SQRT(Inputs!$C$22)))-Inputs!$C$29*SQRT(Inputs!$C$22))) -> 37.615607 | J7: =Inputs!$C$11*Inputs!$C$30-Inputs!$C$11/($B7*Inputs!$C$23)*(($B7*Inputs!$C$23)*Inputs!$C$30*NORMSDIST(-(((LN(Inputs!$C$24/($B7*Inputs!$C$23))+(Inputs!$C$25+Inputs!$C$29^2/2)*Inputs!$C$22)/(Inputs!$C$29*SQRT(Inputs!$C$22)))-Inputs!$C$29*SQRT(Inputs!$C$22)))-Inputs!$C$24*NORMSDIST(-((LN(Inputs!$C$24/($B7*Inputs!$C$23))+(Inputs!$C$25+Inputs!$C$29^2/2)*Inputs!$C$22)/(Inputs!$C$29*SQRT(Inputs!$C$22)))))+Inputs!$C$11/(J$5*Inputs!$C$23)*(Inputs!$C$24*NORMSDIST(((LN(Inputs!$C$24/(J$5*Inputs!$C$23))+(Inputs!$C$25+Inputs!$C$29^2/2)*Inputs!$C$22)/(Inputs!$C$29*SQRT(Inputs!$C$22))))-(J$5*Inputs!$C$23)*Inputs!$C$30*NORMSDIST(((LN(Inputs!$C$24/(J$5*Inputs!$C$23))+(Inputs!$C$25+Inputs!$C$29^2/2)*Inputs!$C$22)/(Inputs!$C$29*SQRT(Inputs!$C$22)))-Inputs!$C$29*SQRT(Inputs!$C$22))) -> 37.310146 | ... O7: =Inputs!$C$11*Inputs!$C$30-Inputs!$C$11/($B7*Inputs!$C$23)*(($B7*Inputs!$C$23)*Inputs!$C$30*NORMSDIST(-(((LN(Inputs!$C$24/($B7*Inputs!$C$23))+(Inputs!$C$25+Inputs!$C$29^2/2)*Inputs!$C$22)/(Inputs!$C$29*SQRT(Inputs!$C$22)))-Inputs!$C$29*SQRT(Inputs!$C$22)))-Inputs!$C$24*NORMSDIST(-((LN(Inputs!$C$24/($B7*Inputs!$C$23))+(Inputs!$C$25+Inputs!$C$29^2/2)*Inputs!$C$22)/(Inputs!$C$29*SQRT(Inputs!$C$22)))))+Inputs!$C$11/(O$5*Inputs!$C$23)*(Inputs!$C$24*NORMSDIST(((LN(Inputs!$C$24/(O$5*Inputs!$C$23))+(Inputs!$C$25+Inputs!$C$29^2/2)*Inputs!$C$22)/(Inputs!$C$29*SQRT(Inputs!$C$22))))-(O$5*Inputs!$C$23)*Inputs!$C$30*NORMSDIST(((LN(Inputs!$C$24/(O$5*Inputs!$C$23))+(Inputs!$C$25+Inputs!$C$29^2/2)*Inputs!$C$22)/(Inputs!$C$29*SQRT(Inputs!$C$22)))-Inputs!$C$29*SQRT(Inputs!$C$22))) -> 36.179018
B8: 0.75 | C8: =Inputs!$C$11*Inputs!$C$30-Inputs!$C$11/($B8*Inputs!$C$23)*(($B8*Inputs!$C$23)*Inputs!$C$30*NORMSDIST(-(((LN(Inputs!$C$24/($B8*Inputs!$C$23))+(Inputs!$C$25+Inputs!$C$29^2/2)*Inputs!$C$22)/(Inputs!$C$29*SQRT(Inputs!$C$22)))-Inputs!$C$29*SQRT(Inputs!$C$22)))-Inputs!$C$24*NORMSDIST(-((LN(Inputs!$C$24/($B8*Inputs!$C$23))+(Inputs!$C$25+Inputs!$C$29^2/2)*Inputs!$C$22)/(Inputs!$C$29*SQRT(Inputs!$C$22)))))+Inputs!$C$11/(C$5*Inputs!$C$23)*(Inputs!$C$24*NORMSDIST(((LN(Inputs!$C$24/(C$5*Inputs!$C$23))+(Inputs!$C$25+Inputs!$C$29^2/2)*Inputs!$C$22)/(Inputs!$C$29*SQRT(Inputs!$C$22))))-(C$5*Inputs!$C$23)*Inputs!$C$30*NORMSDIST(((LN(Inputs!$C$24/(C$5*Inputs!$C$23))+(Inputs!$C$25+Inputs!$C$29^2/2)*Inputs!$C$22)/(Inputs!$C$29*SQRT(Inputs!$C$22)))-Inputs!$C$29*SQRT(Inputs!$C$22))) -> 40.083597 | D8: =Inputs!$C$11*Inputs!$C$30-Inputs!$C$11/($B8*Inputs!$C$23)*(($B8*Inputs!$C$23)*Inputs!$C$30*NORMSDIST(-(((LN(Inputs!$C$24/($B8*Inputs!$C$23))+(Inputs!$C$25+Inputs!$C$29^2/2)*Inputs!$C$22)/(Inputs!$C$29*SQRT(Inputs!$C$22)))-Inputs!$C$29*SQRT(Inputs!$C$22)))-Inputs!$C$24*NORMSDIST(-((LN(Inputs!$C$24/($B8*Inputs!$C$23))+(Inputs!$C$25+Inputs!$C$29^2/2)*Inputs!$C$22)/(Inputs!$C$29*SQRT(Inputs!$C$22)))))+Inputs!$C$11/(D$5*Inputs!$C$23)*(Inputs!$C$24*NORMSDIST(((LN(Inputs!$C$24/(D$5*Inputs!$C$23))+(Inputs!$C$25+Inputs!$C$29^2/2)*Inputs!$C$22)/(Inputs!$C$29*SQRT(Inputs!$C$22))))-(D$5*Inputs!$C$23)*Inputs!$C$30*NORMSDIST(((LN(Inputs!$C$24/(D$5*Inputs!$C$23))+(Inputs!$C$25+Inputs!$C$29^2/2)*Inputs!$C$22)/(Inputs!$C$29*SQRT(Inputs!$C$22)))-Inputs!$C$29*SQRT(Inputs!$C$22))) -> 39.527127 | E8: =Inputs!$C$11*Inputs!$C$30-Inputs!$C$11/($B8*Inputs!$C$23)*(($B8*Inputs!$C$23)*Inputs!$C$30*NORMSDIST(-(((LN(Inputs!$C$24/($B8*Inputs!$C$23))+(Inputs!$C$25+Inputs!$C$29^2/2)*Inputs!$C$22)/(Inputs!$C$29*SQRT(Inputs!$C$22)))-Inputs!$C$29*SQRT(Inputs!$C$22)))-Inputs!$C$24*NORMSDIST(-((LN(Inputs!$C$24/($B8*Inputs!$C$23))+(Inputs!$C$25+Inputs!$C$29^2/2)*Inputs!$C$22)/(Inputs!$C$29*SQRT(Inputs!$C$22)))))+Inputs!$C$11/(E$5*Inputs!$C$23)*(Inputs!$C$24*NORMSDIST(((LN(Inputs!$C$24/(E$5*Inputs!$C$23))+(Inputs!$C$25+Inputs!$C$29^2/2)*Inputs!$C$22)/(Inputs!$C$29*SQRT(Inputs!$C$22))))-(E$5*Inputs!$C$23)*Inputs!$C$30*NORMSDIST(((LN(Inputs!$C$24/(E$5*Inputs!$C$23))+(Inputs!$C$25+Inputs!$C$29^2/2)*Inputs!$C$22)/(Inputs!$C$29*SQRT(Inputs!$C$22)))-Inputs!$C$29*SQRT(Inputs!$C$22))) -> 39.022494 | F8: =Inputs!$C$11*Inputs!$C$30-Inputs!$C$11/($B8*Inputs!$C$23)*(($B8*Inputs!$C$23)*Inputs!$C$30*NORMSDIST(-(((LN(Inputs!$C$24/($B8*Inputs!$C$23))+(Inputs!$C$25+Inputs!$C$29^2/2)*Inputs!$C$22)/(Inputs!$C$29*SQRT(Inputs!$C$22)))-Inputs!$C$29*SQRT(Inputs!$C$22)))-Inputs!$C$24*NORMSDIST(-((LN(Inputs!$C$24/($B8*Inputs!$C$23))+(Inputs!$C$25+Inputs!$C$29^2/2)*Inputs!$C$22)/(Inputs!$C$29*SQRT(Inputs!$C$22)))))+Inputs!$C$11/(F$5*Inputs!$C$23)*(Inputs!$C$24*NORMSDIST(((LN(Inputs!$C$24/(F$5*Inputs!$C$23))+(Inputs!$C$25+Inputs!$C$29^2/2)*Inputs!$C$22)/(Inputs!$C$29*SQRT(Inputs!$C$22))))-(F$5*Inputs!$C$23)*Inputs!$C$30*NORMSDIST(((LN(Inputs!$C$24/(F$5*Inputs!$C$23))+(Inputs!$C$25+Inputs!$C$29^2/2)*Inputs!$C$22)/(Inputs!$C$29*SQRT(Inputs!$C$22)))-Inputs!$C$29*SQRT(Inputs!$C$22))) -> 38.565283 | G8: =Inputs!$C$11*Inputs!$C$30-Inputs!$C$11/($B8*Inputs!$C$23)*(($B8*Inputs!$C$23)*Inputs!$C$30*NORMSDIST(-(((LN(Inputs!$C$24/($B8*Inputs!$C$23))+(Inputs!$C$25+Inputs!$C$29^2/2)*Inputs!$C$22)/(Inputs!$C$29*SQRT(Inputs!$C$22)))-Inputs!$C$29*SQRT(Inputs!$C$22)))-Inputs!$C$24*NORMSDIST(-((LN(Inputs!$C$24/($B8*Inputs!$C$23))+(Inputs!$C$25+Inputs!$C$29^2/2)*Inputs!$C$22)/(Inputs!$C$29*SQRT(Inputs!$C$22)))))+Inputs!$C$11/(G$5*Inputs!$C$23)*(Inputs!$C$24*NORMSDIST(((LN(Inputs!$C$24/(G$5*Inputs!$C$23))+(Inputs!$C$25+Inputs!$C$29^2/2)*Inputs!$C$22)/(Inputs!$C$29*SQRT(Inputs!$C$22))))-(G$5*Inputs!$C$23)*Inputs!$C$30*NORMSDIST(((LN(Inputs!$C$24/(G$5*Inputs!$C$23))+(Inputs!$C$25+Inputs!$C$29^2/2)*Inputs!$C$22)/(Inputs!$C$29*SQRT(Inputs!$C$22)))-Inputs!$C$29*SQRT(Inputs!$C$22))) -> 38.151407 | H8: =Inputs!$C$11*Inputs!$C$30-Inputs!$C$11/($B8*Inputs!$C$23)*(($B8*Inputs!$C$23)*Inputs!$C$30*NORMSDIST(-(((LN(Inputs!$C$24/($B8*Inputs!$C$23))+(Inputs!$C$25+Inputs!$C$29^2/2)*Inputs!$C$22)/(Inputs!$C$29*SQRT(Inputs!$C$22)))-Inputs!$C$29*SQRT(Inputs!$C$22)))-Inputs!$C$24*NORMSDIST(-((LN(Inputs!$C$24/($B8*Inputs!$C$23))+(Inputs!$C$25+Inputs!$C$29^2/2)*Inputs!$C$22)/(Inputs!$C$29*SQRT(Inputs!$C$22)))))+Inputs!$C$11/(H$5*Inputs!$C$23)*(Inputs!$C$24*NORMSDIST(((LN(Inputs!$C$24/(H$5*Inputs!$C$23))+(Inputs!$C$25+Inputs!$C$29^2/2)*Inputs!$C$22)/(Inputs!$C$29*SQRT(Inputs!$C$22))))-(H$5*Inputs!$C$23)*Inputs!$C$30*NORMSDIST(((LN(Inputs!$C$24/(H$5*Inputs!$C$23))+(Inputs!$C$25+Inputs!$C$29^2/2)*Inputs!$C$22)/(Inputs!$C$29*SQRT(Inputs!$C$22)))-Inputs!$C$29*SQRT(Inputs!$C$22))) -> 37.77708 | I8: =Inputs!$C$11*Inputs!$C$30-Inputs!$C$11/($B8*Inputs!$C$23)*(($B8*Inputs!$C$23)*Inputs!$C$30*NORMSDIST(-(((LN(Inputs!$C$24/($B8*Inputs!$C$23))+(Inputs!$C$25+Inputs!$C$29^2/2)*Inputs!$C$22)/(Inputs!$C$29*SQRT(Inputs!$C$22)))-Inputs!$C$29*SQRT(Inputs!$C$22)))-Inputs!$C$24*NORMSDIST(-((LN(Inputs!$C$24/($B8*Inputs!$C$23))+(Inputs!$C$25+Inputs!$C$29^2/2)*Inputs!$C$22)/(Inputs!$C$29*SQRT(Inputs!$C$22)))))+Inputs!$C$11/(I$5*Inputs!$C$23)*(Inputs!$C$24*NORMSDIST(((LN(Inputs!$C$24/(I$5*Inputs!$C$23))+(Inputs!$C$25+Inputs!$C$29^2/2)*Inputs!$C$22)/(Inputs!$C$29*SQRT(Inputs!$C$22))))-(I$5*Inputs!$C$23)*Inputs!$C$30*NORMSDIST(((LN(Inputs!$C$24/(I$5*Inputs!$C$23))+(Inputs!$C$25+Inputs!$C$29^2/2)*Inputs!$C$22)/(Inputs!$C$29*SQRT(Inputs!$C$22)))-Inputs!$C$29*SQRT(Inputs!$C$22))) -> 37.4388 | J8: =Inputs!$C$11*Inputs!$C$30-Inputs!$C$11/($B8*Inputs!$C$23)*(($B8*Inputs!$C$23)*Inputs!$C$30*NORMSDIST(-(((LN(Inputs!$C$24/($B8*Inputs!$C$23))+(Inputs!$C$25+Inputs!$C$29^2/2)*Inputs!$C$22)/(Inputs!$C$29*SQRT(Inputs!$C$22)))-Inputs!$C$29*SQRT(Inputs!$C$22)))-Inputs!$C$24*NORMSDIST(-((LN(Inputs!$C$24/($B8*Inputs!$C$23))+(Inputs!$C$25+Inputs!$C$29^2/2)*Inputs!$C$22)/(Inputs!$C$29*SQRT(Inputs!$C$22)))))+Inputs!$C$11/(J$5*Inputs!$C$23)*(Inputs!$C$24*NORMSDIST(((LN(Inputs!$C$24/(J$5*Inputs!$C$23))+(Inputs!$C$25+Inputs!$C$29^2/2)*Inputs!$C$22)/(Inputs!$C$29*SQRT(Inputs!$C$22))))-(J$5*Inputs!$C$23)*Inputs!$C$30*NORMSDIST(((LN(Inputs!$C$24/(J$5*Inputs!$C$23))+(Inputs!$C$25+Inputs!$C$29^2/2)*Inputs!$C$22)/(Inputs!$C$29*SQRT(Inputs!$C$22)))-Inputs!$C$29*SQRT(Inputs!$C$22))) -> 37.13334 | ... O8: =Inputs!$C$11*Inputs!$C$30-Inputs!$C$11/($B8*Inputs!$C$23)*(($B8*Inputs!$C$23)*Inputs!$C$30*NORMSDIST(-(((LN(Inputs!$C$24/($B8*Inputs!$C$23))+(Inputs!$C$25+Inputs!$C$29^2/2)*Inputs!$C$22)/(Inputs!$C$29*SQRT(Inputs!$C$22)))-Inputs!$C$29*SQRT(Inputs!$C$22)))-Inputs!$C$24*NORMSDIST(-((LN(Inputs!$C$24/($B8*Inputs!$C$23))+(Inputs!$C$25+Inputs!$C$29^2/2)*Inputs!$C$22)/(Inputs!$C$29*SQRT(Inputs!$C$22)))))+Inputs!$C$11/(O$5*Inputs!$C$23)*(Inputs!$C$24*NORMSDIST(((LN(Inputs!$C$24/(O$5*Inputs!$C$23))+(Inputs!$C$25+Inputs!$C$29^2/2)*Inputs!$C$22)/(Inputs!$C$29*SQRT(Inputs!$C$22))))-(O$5*Inputs!$C$23)*Inputs!$C$30*NORMSDIST(((LN(Inputs!$C$24/(O$5*Inputs!$C$23))+(Inputs!$C$25+Inputs!$C$29^2/2)*Inputs!$C$22)/(Inputs!$C$29*SQRT(Inputs!$C$22)))-Inputs!$C$29*SQRT(Inputs!$C$22))) -> 36.002211
B9: 0.775 | C9: =Inputs!$C$11*Inputs!$C$30-Inputs!$C$11/($B9*Inputs!$C$23)*(($B9*Inputs!$C$23)*Inputs!$C$30*NORMSDIST(-(((LN(Inputs!$C$24/($B9*Inputs!$C$23))+(Inputs!$C$25+Inputs!$C$29^2/2)*Inputs!$C$22)/(Inputs!$C$29*SQRT(Inputs!$C$22)))-Inputs!$C$29*SQRT(Inputs!$C$22)))-Inputs!$C$24*NORMSDIST(-((LN(Inputs!$C$24/($B9*Inputs!$C$23))+(Inputs!$C$25+Inputs!$C$29^2/2)*Inputs!$C$22)/(Inputs!$C$29*SQRT(Inputs!$C$22)))))+Inputs!$C$11/(C$5*Inputs!$C$23)*(Inputs!$C$24*NORMSDIST(((LN(Inputs!$C$24/(C$5*Inputs!$C$23))+(Inputs!$C$25+Inputs!$C$29^2/2)*Inputs!$C$22)/(Inputs!$C$29*SQRT(Inputs!$C$22))))-(C$5*Inputs!$C$23)*Inputs!$C$30*NORMSDIST(((LN(Inputs!$C$24/(C$5*Inputs!$C$23))+(Inputs!$C$25+Inputs!$C$29^2/2)*Inputs!$C$22)/(Inputs!$C$29*SQRT(Inputs!$C$22)))-Inputs!$C$29*SQRT(Inputs!$C$22))) -> 39.886519 | D9: =Inputs!$C$11*Inputs!$C$30-Inputs!$C$11/($B9*Inputs!$C$23)*(($B9*Inputs!$C$23)*Inputs!$C$30*NORMSDIST(-(((LN(Inputs!$C$24/($B9*Inputs!$C$23))+(Inputs!$C$25+Inputs!$C$29^2/2)*Inputs!$C$22)/(Inputs!$C$29*SQRT(Inputs!$C$22)))-Inputs!$C$29*SQRT(Inputs!$C$22)))-Inputs!$C$24*NORMSDIST(-((LN(Inputs!$C$24/($B9*Inputs!$C$23))+(Inputs!$C$25+Inputs!$C$29^2/2)*Inputs!$C$22)/(Inputs!$C$29*SQRT(Inputs!$C$22)))))+Inputs!$C$11/(D$5*Inputs!$C$23)*(Inputs!$C$24*NORMSDIST(((LN(Inputs!$C$24/(D$5*Inputs!$C$23))+(Inputs!$C$25+Inputs!$C$29^2/2)*Inputs!$C$22)/(Inputs!$C$29*SQRT(Inputs!$C$22))))-(D$5*Inputs!$C$23)*Inputs!$C$30*NORMSDIST(((LN(Inputs!$C$24/(D$5*Inputs!$C$23))+(Inputs!$C$25+Inputs!$C$29^2/2)*Inputs!$C$22)/(Inputs!$C$29*SQRT(Inputs!$C$22)))-Inputs!$C$29*SQRT(Inputs!$C$22))) -> 39.330049 | E9: =Inputs!$C$11*Inputs!$C$30-Inputs!$C$11/($B9*Inputs!$C$23)*(($B9*Inputs!$C$23)*Inputs!$C$30*NORMSDIST(-(((LN(Inputs!$C$24/($B9*Inputs!$C$23))+(Inputs!$C$25+Inputs!$C$29^2/2)*Inputs!$C$22)/(Inputs!$C$29*SQRT(Inputs!$C$22)))-Inputs!$C$29*SQRT(Inputs!$C$22)))-Inputs!$C$24*NORMSDIST(-((LN(Inputs!$C$24/($B9*Inputs!$C$23))+(Inputs!$C$25+Inputs!$C$29^2/2)*Inputs!$C$22)/(Inputs!$C$29*SQRT(Inputs!$C$22)))))+Inputs!$C$11/(E$5*Inputs!$C$23)*(Inputs!$C$24*NORMSDIST(((LN(Inputs!$C$24/(E$5*Inputs!$C$23))+(Inputs!$C$25+Inputs!$C$29^2/2)*Inputs!$C$22)/(Inputs!$C$29*SQRT(Inputs!$C$22))))-(E$5*Inputs!$C$23)*Inputs!$C$30*NORMSDIST(((LN(Inputs!$C$24/(E$5*Inputs!$C$23))+(Inputs!$C$25+Inputs!$C$29^2/2)*Inputs!$C$22)/(Inputs!$C$29*SQRT(Inputs!$C$22)))-Inputs!$C$29*SQRT(Inputs!$C$22))) -> 38.825416 | F9: =Inputs!$C$11*Inputs!$C$30-Inputs!$C$11/($B9*Inputs!$C$23)*(($B9*Inputs!$C$23)*Inputs!$C$30*NORMSDIST(-(((LN(Inputs!$C$24/($B9*Inputs!$C$23))+(Inputs!$C$25+Inputs!$C$29^2/2)*Inputs!$C$22)/(Inputs!$C$29*SQRT(Inputs!$C$22)))-Inputs!$C$29*SQRT(Inputs!$C$22)))-Inputs!$C$24*NORMSDIST(-((LN(Inputs!$C$24/($B9*Inputs!$C$23))+(Inputs!$C$25+Inputs!$C$29^2/2)*Inputs!$C$22)/(Inputs!$C$29*SQRT(Inputs!$C$22)))))+Inputs!$C$11/(F$5*Inputs!$C$23)*(Inputs!$C$24*NORMSDIST(((LN(Inputs!$C$24/(F$5*Inputs!$C$23))+(Inputs!$C$25+Inputs!$C$29^2/2)*Inputs!$C$22)/(Inputs!$C$29*SQRT(Inputs!$C$22))))-(F$5*Inputs!$C$23)*Inputs!$C$30*NORMSDIST(((LN(Inputs!$C$24/(F$5*Inputs!$C$23))+(Inputs!$C$25+Inputs!$C$29^2/2)*Inputs!$C$22)/(Inputs!$C$29*SQRT(Inputs!$C$22)))-Inputs!$C$29*SQRT(Inputs!$C$22))) -> 38.368205 | G9: =Inputs!$C$11*Inputs!$C$30-Inputs!$C$11/($B9*Inputs!$C$23)*(($B9*Inputs!$C$23)*Inputs!$C$30*NORMSDIST(-(((LN(Inputs!$C$24/($B9*Inputs!$C$23))+(Inputs!$C$25+Inputs!$C$29^2/2)*Inputs!$C$22)/(Inputs!$C$29*SQRT(Inputs!$C$22)))-Inputs!$C$29*SQRT(Inputs!$C$22)))-Inputs!$C$24*NORMSDIST(-((LN(Inputs!$C$24/($B9*Inputs!$C$23))+(Inputs!$C$25+Inputs!$C$29^2/2)*Inputs!$C$22)/(Inputs!$C$29*SQRT(Inputs!$C$22)))))+Inputs!$C$11/(G$5*Inputs!$C$23)*(Inputs!$C$24*NORMSDIST(((LN(Inputs!$C$24/(G$5*Inputs!$C$23))+(Inputs!$C$25+Inputs!$C$29^2/2)*Inputs!$C$22)/(Inputs!$C$29*SQRT(Inputs!$C$22))))-(G$5*Inputs!$C$23)*Inputs!$C$30*NORMSDIST(((LN(Inputs!$C$24/(G$5*Inputs!$C$23))+(Inputs!$C$25+Inputs!$C$29^2/2)*Inputs!$C$22)/(Inputs!$C$29*SQRT(Inputs!$C$22)))-Inputs!$C$29*SQRT(Inputs!$C$22))) -> 37.954329 | H9: =Inputs!$C$11*Inputs!$C$30-Inputs!$C$11/($B9*Inputs!$C$23)*(($B9*Inputs!$C$23)*Inputs!$C$30*NORMSDIST(-(((LN(Inputs!$C$24/($B9*Inputs!$C$23))+(Inputs!$C$25+Inputs!$C$29^2/2)*Inputs!$C$22)/(Inputs!$C$29*SQRT(Inputs!$C$22)))-Inputs!$C$29*SQRT(Inputs!$C$22)))-Inputs!$C$24*NORMSDIST(-((LN(Inputs!$C$24/($B9*Inputs!$C$23))+(Inputs!$C$25+Inputs!$C$29^2/2)*Inputs!$C$22)/(Inputs!$C$29*SQRT(Inputs!$C$22)))))+Inputs!$C$11/(H$5*Inputs!$C$23)*(Inputs!$C$24*NORMSDIST(((LN(Inputs!$C$24/(H$5*Inputs!$C$23))+(Inputs!$C$25+Inputs!$C$29^2/2)*Inputs!$C$22)/(Inputs!$C$29*SQRT(Inputs!$C$22))))-(H$5*Inputs!$C$23)*Inputs!$C$30*NORMSDIST(((LN(Inputs!$C$24/(H$5*Inputs!$C$23))+(Inputs!$C$25+Inputs!$C$29^2/2)*Inputs!$C$22)/(Inputs!$C$29*SQRT(Inputs!$C$22)))-Inputs!$C$29*SQRT(Inputs!$C$22))) -> 37.580002 | I9: =Inputs!$C$11*Inputs!$C$30-Inputs!$C$11/($B9*Inputs!$C$23)*(($B9*Inputs!$C$23)*Inputs!$C$30*NORMSDIST(-(((LN(Inputs!$C$24/($B9*Inputs!$C$23))+(Inputs!$C$25+Inputs!$C$29^2/2)*Inputs!$C$22)/(Inputs!$C$29*SQRT(Inputs!$C$22)))-Inputs!$C$29*SQRT(Inputs!$C$22)))-Inputs!$C$24*NORMSDIST(-((LN(Inputs!$C$24/($B9*Inputs!$C$23))+(Inputs!$C$25+Inputs!$C$29^2/2)*Inputs!$C$22)/(Inputs!$C$29*SQRT(Inputs!$C$22)))))+Inputs!$C$11/(I$5*Inputs!$C$23)*(Inputs!$C$24*NORMSDIST(((LN(Inputs!$C$24/(I$5*Inputs!$C$23))+(Inputs!$C$25+Inputs!$C$29^2/2)*Inputs!$C$22)/(Inputs!$C$29*SQRT(Inputs!$C$22))))-(I$5*Inputs!$C$23)*Inputs!$C$30*NORMSDIST(((LN(Inputs!$C$24/(I$5*Inputs!$C$23))+(Inputs!$C$25+Inputs!$C$29^2/2)*Inputs!$C$22)/(Inputs!$C$29*SQRT(Inputs!$C$22)))-Inputs!$C$29*SQRT(Inputs!$C$22))) -> 37.241722 | J9: =Inputs!$C$11*Inputs!$C$30-Inputs!$C$11/($B9*Inputs!$C$23)*(($B9*Inputs!$C$23)*Inputs!$C$30*NORMSDIST(-(((LN(Inputs!$C$24/($B9*Inputs!$C$23))+(Inputs!$C$25+Inputs!$C$29^2/2)*Inputs!$C$22)/(Inputs!$C$29*SQRT(Inputs!$C$22)))-Inputs!$C$29*SQRT(Inputs!$C$22)))-Inputs!$C$24*NORMSDIST(-((LN(Inputs!$C$24/($B9*Inputs!$C$23))+(Inputs!$C$25+Inputs!$C$29^2/2)*Inputs!$C$22)/(Inputs!$C$29*SQRT(Inputs!$C$22)))))+Inputs!$C$11/(J$5*Inputs!$C$23)*(Inputs!$C$24*NORMSDIST(((LN(Inputs!$C$24/(J$5*Inputs!$C$23))+(Inputs!$C$25+Inputs!$C$29^2/2)*Inputs!$C$22)/(Inputs!$C$29*SQRT(Inputs!$C$22))))-(J$5*Inputs!$C$23)*Inputs!$C$30*NORMSDIST(((LN(Inputs!$C$24/(J$5*Inputs!$C$23))+(Inputs!$C$25+Inputs!$C$29^2/2)*Inputs!$C$22)/(Inputs!$C$29*SQRT(Inputs!$C$22)))-Inputs!$C$29*SQRT(Inputs!$C$22))) -> 36.936262 | ... O9: =Inputs!$C$11*Inputs!$C$30-Inputs!$C$11/($B9*Inputs!$C$23)*(($B9*Inputs!$C$23)*Inputs!$C$30*NORMSDIST(-(((LN(Inputs!$C$24/($B9*Inputs!$C$23))+(Inputs!$C$25+Inputs!$C$29^2/2)*Inputs!$C$22)/(Inputs!$C$29*SQRT(Inputs!$C$22)))-Inputs!$C$29*SQRT(Inputs!$C$22)))-Inputs!$C$24*NORMSDIST(-((LN(Inputs!$C$24/($B9*Inputs!$C$23))+(Inputs!$C$25+Inputs!$C$29^2/2)*Inputs!$C$22)/(Inputs!$C$29*SQRT(Inputs!$C$22)))))+Inputs!$C$11/(O$5*Inputs!$C$23)*(Inputs!$C$24*NORMSDIST(((LN(Inputs!$C$24/(O$5*Inputs!$C$23))+(Inputs!$C$25+Inputs!$C$29^2/2)*Inputs!$C$22)/(Inputs!$C$29*SQRT(Inputs!$C$22))))-(O$5*Inputs!$C$23)*Inputs!$C$30*NORMSDIST(((LN(Inputs!$C$24/(O$5*Inputs!$C$23))+(Inputs!$C$25+Inputs!$C$29^2/2)*Inputs!$C$22)/(Inputs!$C$29*SQRT(Inputs!$C$22)))-Inputs!$C$29*SQRT(Inputs!$C$22))) -> 35.805133
B10: 0.8 | C10: =Inputs!$C$11*Inputs!$C$30-Inputs!$C$11/($B10*Inputs!$C$23)*(($B10*Inputs!$C$23)*Inputs!$C$30*NORMSDIST(-(((LN(Inputs!$C$24/($B10*Inputs!$C$23))+(Inputs!$C$25+Inputs!$C$29^2/2)*Inputs!$C$22)/(Inputs!$C$29*SQRT(Inputs!$C$22)))-Inputs!$C$29*SQRT(Inputs!$C$22)))-Inputs!$C$24*NORMSDIST(-((LN(Inputs!$C$24/($B10*Inputs!$C$23))+(Inputs!$C$25+Inputs!$C$29^2/2)*Inputs!$C$22)/(Inputs!$C$29*SQRT(Inputs!$C$22)))))+Inputs!$C$11/(C$5*Inputs!$C$23)*(Inputs!$C$24*NORMSDIST(((LN(Inputs!$C$24/(C$5*Inputs!$C$23))+(Inputs!$C$25+Inputs!$C$29^2/2)*Inputs!$C$22)/(Inputs!$C$29*SQRT(Inputs!$C$22))))-(C$5*Inputs!$C$23)*Inputs!$C$30*NORMSDIST(((LN(Inputs!$C$24/(C$5*Inputs!$C$23))+(Inputs!$C$25+Inputs!$C$29^2/2)*Inputs!$C$22)/(Inputs!$C$29*SQRT(Inputs!$C$22)))-Inputs!$C$29*SQRT(Inputs!$C$22))) -> 39.669421 | D10: =Inputs!$C$11*Inputs!$C$30-Inputs!$C$11/($B10*Inputs!$C$23)*(($B10*Inputs!$C$23)*Inputs!$C$30*NORMSDIST(-(((LN(Inputs!$C$24/($B10*Inputs!$C$23))+(Inputs!$C$25+Inputs!$C$29^2/2)*Inputs!$C$22)/(Inputs!$C$29*SQRT(Inputs!$C$22)))-Inputs!$C$29*SQRT(Inputs!$C$22)))-Inputs!$C$24*NORMSDIST(-((LN(Inputs!$C$24/($B10*Inputs!$C$23))+(Inputs!$C$25+Inputs!$C$29^2/2)*Inputs!$C$22)/(Inputs!$C$29*SQRT(Inputs!$C$22)))))+Inputs!$C$11/(D$5*Inputs!$C$23)*(Inputs!$C$24*NORMSDIST(((LN(Inputs!$C$24/(D$5*Inputs!$C$23))+(Inputs!$C$25+Inputs!$C$29^2/2)*Inputs!$C$22)/(Inputs!$C$29*SQRT(Inputs!$C$22))))-(D$5*Inputs!$C$23)*Inputs!$C$30*NORMSDIST(((LN(Inputs!$C$24/(D$5*Inputs!$C$23))+(Inputs!$C$25+Inputs!$C$29^2/2)*Inputs!$C$22)/(Inputs!$C$29*SQRT(Inputs!$C$22)))-Inputs!$C$29*SQRT(Inputs!$C$22))) -> 39.112952 | E10: =Inputs!$C$11*Inputs!$C$30-Inputs!$C$11/($B10*Inputs!$C$23)*(($B10*Inputs!$C$23)*Inputs!$C$30*NORMSDIST(-(((LN(Inputs!$C$24/($B10*Inputs!$C$23))+(Inputs!$C$25+Inputs!$C$29^2/2)*Inputs!$C$22)/(Inputs!$C$29*SQRT(Inputs!$C$22)))-Inputs!$C$29*SQRT(Inputs!$C$22)))-Inputs!$C$24*NORMSDIST(-((LN(Inputs!$C$24/($B10*Inputs!$C$23))+(Inputs!$C$25+Inputs!$C$29^2/2)*Inputs!$C$22)/(Inputs!$C$29*SQRT(Inputs!$C$22)))))+Inputs!$C$11/(E$5*Inputs!$C$23)*(Inputs!$C$24*NORMSDIST(((LN(Inputs!$C$24/(E$5*Inputs!$C$23))+(Inputs!$C$25+Inputs!$C$29^2/2)*Inputs!$C$22)/(Inputs!$C$29*SQRT(Inputs!$C$22))))-(E$5*Inputs!$C$23)*Inputs!$C$30*NORMSDIST(((LN(Inputs!$C$24/(E$5*Inputs!$C$23))+(Inputs!$C$25+Inputs!$C$29^2/2)*Inputs!$C$22)/(Inputs!$C$29*SQRT(Inputs!$C$22)))-Inputs!$C$29*SQRT(Inputs!$C$22))) -> 38.608318 | F10: =Inputs!$C$11*Inputs!$C$30-Inputs!$C$11/($B10*Inputs!$C$23)*(($B10*Inputs!$C$23)*Inputs!$C$30*NORMSDIST(-(((LN(Inputs!$C$24/($B10*Inputs!$C$23))+(Inputs!$C$25+Inputs!$C$29^2/2)*Inputs!$C$22)/(Inputs!$C$29*SQRT(Inputs!$C$22)))-Inputs!$C$29*SQRT(Inputs!$C$22)))-Inputs!$C$24*NORMSDIST(-((LN(Inputs!$C$24/($B10*Inputs!$C$23))+(Inputs!$C$25+Inputs!$C$29^2/2)*Inputs!$C$22)/(Inputs!$C$29*SQRT(Inputs!$C$22)))))+Inputs!$C$11/(F$5*Inputs!$C$23)*(Inputs!$C$24*NORMSDIST(((LN(Inputs!$C$24/(F$5*Inputs!$C$23))+(Inputs!$C$25+Inputs!$C$29^2/2)*Inputs!$C$22)/(Inputs!$C$29*SQRT(Inputs!$C$22))))-(F$5*Inputs!$C$23)*Inputs!$C$30*NORMSDIST(((LN(Inputs!$C$24/(F$5*Inputs!$C$23))+(Inputs!$C$25+Inputs!$C$29^2/2)*Inputs!$C$22)/(Inputs!$C$29*SQRT(Inputs!$C$22)))-Inputs!$C$29*SQRT(Inputs!$C$22))) -> 38.151108 | G10: =Inputs!$C$11*Inputs!$C$30-Inputs!$C$11/($B10*Inputs!$C$23)*(($B10*Inputs!$C$23)*Inputs!$C$30*NORMSDIST(-(((LN(Inputs!$C$24/($B10*Inputs!$C$23))+(Inputs!$C$25+Inputs!$C$29^2/2)*Inputs!$C$22)/(Inputs!$C$29*SQRT(Inputs!$C$22)))-Inputs!$C$29*SQRT(Inputs!$C$22)))-Inputs!$C$24*NORMSDIST(-((LN(Inputs!$C$24/($B10*Inputs!$C$23))+(Inputs!$C$25+Inputs!$C$29^2/2)*Inputs!$C$22)/(Inputs!$C$29*SQRT(Inputs!$C$22)))))+Inputs!$C$11/(G$5*Inputs!$C$23)*(Inputs!$C$24*NORMSDIST(((LN(Inputs!$C$24/(G$5*Inputs!$C$23))+(Inputs!$C$25+Inputs!$C$29^2/2)*Inputs!$C$22)/(Inputs!$C$29*SQRT(Inputs!$C$22))))-(G$5*Inputs!$C$23)*Inputs!$C$30*NORMSDIST(((LN(Inputs!$C$24/(G$5*Inputs!$C$23))+(Inputs!$C$25+Inputs!$C$29^2/2)*Inputs!$C$22)/(Inputs!$C$29*SQRT(Inputs!$C$22)))-Inputs!$C$29*SQRT(Inputs!$C$22))) -> 37.737232 | H10: =Inputs!$C$11*Inputs!$C$30-Inputs!$C$11/($B10*Inputs!$C$23)*(($B10*Inputs!$C$23)*Inputs!$C$30*NORMSDIST(-(((LN(Inputs!$C$24/($B10*Inputs!$C$23))+(Inputs!$C$25+Inputs!$C$29^2/2)*Inputs!$C$22)/(Inputs!$C$29*SQRT(Inputs!$C$22)))-Inputs!$C$29*SQRT(Inputs!$C$22)))-Inputs!$C$24*NORMSDIST(-((LN(Inputs!$C$24/($B10*Inputs!$C$23))+(Inputs!$C$25+Inputs!$C$29^2/2)*Inputs!$C$22)/(Inputs!$C$29*SQRT(Inputs!$C$22)))))+Inputs!$C$11/(H$5*Inputs!$C$23)*(Inputs!$C$24*NORMSDIST(((LN(Inputs!$C$24/(H$5*Inputs!$C$23))+(Inputs!$C$25+Inputs!$C$29^2/2)*Inputs!$C$22)/(Inputs!$C$29*SQRT(Inputs!$C$22))))-(H$5*Inputs!$C$23)*Inputs!$C$30*NORMSDIST(((LN(Inputs!$C$24/(H$5*Inputs!$C$23))+(Inputs!$C$25+Inputs!$C$29^2/2)*Inputs!$C$22)/(Inputs!$C$29*SQRT(Inputs!$C$22)))-Inputs!$C$29*SQRT(Inputs!$C$22))) -> 37.362904 | I10: =Inputs!$C$11*Inputs!$C$30-Inputs!$C$11/($B10*Inputs!$C$23)*(($B10*Inputs!$C$23)*Inputs!$C$30*NORMSDIST(-(((LN(Inputs!$C$24/($B10*Inputs!$C$23))+(Inputs!$C$25+Inputs!$C$29^2/2)*Inputs!$C$22)/(Inputs!$C$29*SQRT(Inputs!$C$22)))-Inputs!$C$29*SQRT(Inputs!$C$22)))-Inputs!$C$24*NORMSDIST(-((LN(Inputs!$C$24/($B10*Inputs!$C$23))+(Inputs!$C$25+Inputs!$C$29^2/2)*Inputs!$C$22)/(Inputs!$C$29*SQRT(Inputs!$C$22)))))+Inputs!$C$11/(I$5*Inputs!$C$23)*(Inputs!$C$24*NORMSDIST(((LN(Inputs!$C$24/(I$5*Inputs!$C$23))+(Inputs!$C$25+Inputs!$C$29^2/2)*Inputs!$C$22)/(Inputs!$C$29*SQRT(Inputs!$C$22))))-(I$5*Inputs!$C$23)*Inputs!$C$30*NORMSDIST(((LN(Inputs!$C$24/(I$5*Inputs!$C$23))+(Inputs!$C$25+Inputs!$C$29^2/2)*Inputs!$C$22)/(Inputs!$C$29*SQRT(Inputs!$C$22)))-Inputs!$C$29*SQRT(Inputs!$C$22))) -> 37.024625 | J10: =Inputs!$C$11*Inputs!$C$30-Inputs!$C$11/($B10*Inputs!$C$23)*(($B10*Inputs!$C$23)*Inputs!$C$30*NORMSDIST(-(((LN(Inputs!$C$24/($B10*Inputs!$C$23))+(Inputs!$C$25+Inputs!$C$29^2/2)*Inputs!$C$22)/(Inputs!$C$29*SQRT(Inputs!$C$22)))-Inputs!$C$29*SQRT(Inputs!$C$22)))-Inputs!$C$24*NORMSDIST(-((LN(Inputs!$C$24/($B10*Inputs!$C$23))+(Inputs!$C$25+Inputs!$C$29^2/2)*Inputs!$C$22)/(Inputs!$C$29*SQRT(Inputs!$C$22)))))+Inputs!$C$11/(J$5*Inputs!$C$23)*(Inputs!$C$24*NORMSDIST(((LN(Inputs!$C$24/(J$5*Inputs!$C$23))+(Inputs!$C$25+Inputs!$C$29^2/2)*Inputs!$C$22)/(Inputs!$C$29*SQRT(Inputs!$C$22))))-(J$5*Inputs!$C$23)*Inputs!$C$30*NORMSDIST(((LN(Inputs!$C$24/(J$5*Inputs!$C$23))+(Inputs!$C$25+Inputs!$C$29^2/2)*Inputs!$C$22)/(Inputs!$C$29*SQRT(Inputs!$C$22)))-Inputs!$C$29*SQRT(Inputs!$C$22))) -> 36.719164 | ... O10: =Inputs!$C$11*Inputs!$C$30-Inputs!$C$11/($B10*Inputs!$C$23)*(($B10*Inputs!$C$23)*Inputs!$C$30*NORMSDIST(-(((LN(Inputs!$C$24/($B10*Inputs!$C$23))+(Inputs!$C$25+Inputs!$C$29^2/2)*Inputs!$C$22)/(Inputs!$C$29*SQRT(Inputs!$C$22)))-Inputs!$C$29*SQRT(Inputs!$C$22)))-Inputs!$C$24*NORMSDIST(-((LN(Inputs!$C$24/($B10*Inputs!$C$23))+(Inputs!$C$25+Inputs!$C$29^2/2)*Inputs!$C$22)/(Inputs!$C$29*SQRT(Inputs!$C$22)))))+Inputs!$C$11/(O$5*Inputs!$C$23)*(Inputs!$C$24*NORMSDIST(((LN(Inputs!$C$24/(O$5*Inputs!$C$23))+(Inputs!$C$25+Inputs!$C$29^2/2)*Inputs!$C$22)/(Inputs!$C$29*SQRT(Inputs!$C$22))))-(O$5*Inputs!$C$23)*Inputs!$C$30*NORMSDIST(((LN(Inputs!$C$24/(O$5*Inputs!$C$23))+(Inputs!$C$25+Inputs!$C$29^2/2)*Inputs!$C$22)/(Inputs!$C$29*SQRT(Inputs!$C$22)))-Inputs!$C$29*SQRT(Inputs!$C$22))) -> 35.588036
B11: 0.825 | C11: =Inputs!$C$11*Inputs!$C$30-Inputs!$C$11/($B11*Inputs!$C$23)*(($B11*Inputs!$C$23)*Inputs!$C$30*NORMSDIST(-(((LN(Inputs!$C$24/($B11*Inputs!$C$23))+(Inputs!$C$25+Inputs!$C$29^2/2)*Inputs!$C$22)/(Inputs!$C$29*SQRT(Inputs!$C$22)))-Inputs!$C$29*SQRT(Inputs!$C$22)))-Inputs!$C$24*NORMSDIST(-((LN(Inputs!$C$24/($B11*Inputs!$C$23))+(Inputs!$C$25+Inputs!$C$29^2/2)*Inputs!$C$22)/(Inputs!$C$29*SQRT(Inputs!$C$22)))))+Inputs!$C$11/(C$5*Inputs!$C$23)*(Inputs!$C$24*NORMSDIST(((LN(Inputs!$C$24/(C$5*Inputs!$C$23))+(Inputs!$C$25+Inputs!$C$29^2/2)*Inputs!$C$22)/(Inputs!$C$29*SQRT(Inputs!$C$22))))-(C$5*Inputs!$C$23)*Inputs!$C$30*NORMSDIST(((LN(Inputs!$C$24/(C$5*Inputs!$C$23))+(Inputs!$C$25+Inputs!$C$29^2/2)*Inputs!$C$22)/(Inputs!$C$29*SQRT(Inputs!$C$22)))-Inputs!$C$29*SQRT(Inputs!$C$22))) -> 39.432816 | D11: =Inputs!$C$11*Inputs!$C$30-Inputs!$C$11/($B11*Inputs!$C$23)*(($B11*Inputs!$C$23)*Inputs!$C$30*NORMSDIST(-(((LN(Inputs!$C$24/($B11*Inputs!$C$23))+(Inputs!$C$25+Inputs!$C$29^2/2)*Inputs!$C$22)/(Inputs!$C$29*SQRT(Inputs!$C$22)))-Inputs!$C$29*SQRT(Inputs!$C$22)))-Inputs!$C$24*NORMSDIST(-((LN(Inputs!$C$24/($B11*Inputs!$C$23))+(Inputs!$C$25+Inputs!$C$29^2/2)*Inputs!$C$22)/(Inputs!$C$29*SQRT(Inputs!$C$22)))))+Inputs!$C$11/(D$5*Inputs!$C$23)*(Inputs!$C$24*NORMSDIST(((LN(Inputs!$C$24/(D$5*Inputs!$C$23))+(Inputs!$C$25+Inputs!$C$29^2/2)*Inputs!$C$22)/(Inputs!$C$29*SQRT(Inputs!$C$22))))-(D$5*Inputs!$C$23)*Inputs!$C$30*NORMSDIST(((LN(Inputs!$C$24/(D$5*Inputs!$C$23))+(Inputs!$C$25+Inputs!$C$29^2/2)*Inputs!$C$22)/(Inputs!$C$29*SQRT(Inputs!$C$22)))-Inputs!$C$29*SQRT(Inputs!$C$22))) -> 38.876347 | E11: =Inputs!$C$11*Inputs!$C$30-Inputs!$C$11/($B11*Inputs!$C$23)*(($B11*Inputs!$C$23)*Inputs!$C$30*NORMSDIST(-(((LN(Inputs!$C$24/($B11*Inputs!$C$23))+(Inputs!$C$25+Inputs!$C$29^2/2)*Inputs!$C$22)/(Inputs!$C$29*SQRT(Inputs!$C$22)))-Inputs!$C$29*SQRT(Inputs!$C$22)))-Inputs!$C$24*NORMSDIST(-((LN(Inputs!$C$24/($B11*Inputs!$C$23))+(Inputs!$C$25+Inputs!$C$29^2/2)*Inputs!$C$22)/(Inputs!$C$29*SQRT(Inputs!$C$22)))))+Inputs!$C$11/(E$5*Inputs!$C$23)*(Inputs!$C$24*NORMSDIST(((LN(Inputs!$C$24/(E$5*Inputs!$C$23))+(Inputs!$C$25+Inputs!$C$29^2/2)*Inputs!$C$22)/(Inputs!$C$29*SQRT(Inputs!$C$22))))-(E$5*Inputs!$C$23)*Inputs!$C$30*NORMSDIST(((LN(Inputs!$C$24/(E$5*Inputs!$C$23))+(Inputs!$C$25+Inputs!$C$29^2/2)*Inputs!$C$22)/(Inputs!$C$29*SQRT(Inputs!$C$22)))-Inputs!$C$29*SQRT(Inputs!$C$22))) -> 38.371713 | F11: =Inputs!$C$11*Inputs!$C$30-Inputs!$C$11/($B11*Inputs!$C$23)*(($B11*Inputs!$C$23)*Inputs!$C$30*NORMSDIST(-(((LN(Inputs!$C$24/($B11*Inputs!$C$23))+(Inputs!$C$25+Inputs!$C$29^2/2)*Inputs!$C$22)/(Inputs!$C$29*SQRT(Inputs!$C$22)))-Inputs!$C$29*SQRT(Inputs!$C$22)))-Inputs!$C$24*NORMSDIST(-((LN(Inputs!$C$24/($B11*Inputs!$C$23))+(Inputs!$C$25+Inputs!$C$29^2/2)*Inputs!$C$22)/(Inputs!$C$29*SQRT(Inputs!$C$22)))))+Inputs!$C$11/(F$5*Inputs!$C$23)*(Inputs!$C$24*NORMSDIST(((LN(Inputs!$C$24/(F$5*Inputs!$C$23))+(Inputs!$C$25+Inputs!$C$29^2/2)*Inputs!$C$22)/(Inputs!$C$29*SQRT(Inputs!$C$22))))-(F$5*Inputs!$C$23)*Inputs!$C$30*NORMSDIST(((LN(Inputs!$C$24/(F$5*Inputs!$C$23))+(Inputs!$C$25+Inputs!$C$29^2/2)*Inputs!$C$22)/(Inputs!$C$29*SQRT(Inputs!$C$22)))-Inputs!$C$29*SQRT(Inputs!$C$22))) -> 37.914503 | G11: =Inputs!$C$11*Inputs!$C$30-Inputs!$C$11/($B11*Inputs!$C$23)*(($B11*Inputs!$C$23)*Inputs!$C$30*NORMSDIST(-(((LN(Inputs!$C$24/($B11*Inputs!$C$23))+(Inputs!$C$25+Inputs!$C$29^2/2)*Inputs!$C$22)/(Inputs!$C$29*SQRT(Inputs!$C$22)))-Inputs!$C$29*SQRT(Inputs!$C$22)))-Inputs!$C$24*NORMSDIST(-((LN(Inputs!$C$24/($B11*Inputs!$C$23))+(Inputs!$C$25+Inputs!$C$29^2/2)*Inputs!$C$22)/(Inputs!$C$29*SQRT(Inputs!$C$22)))))+Inputs!$C$11/(G$5*Inputs!$C$23)*(Inputs!$C$24*NORMSDIST(((LN(Inputs!$C$24/(G$5*Inputs!$C$23))+(Inputs!$C$25+Inputs!$C$29^2/2)*Inputs!$C$22)/(Inputs!$C$29*SQRT(Inputs!$C$22))))-(G$5*Inputs!$C$23)*Inputs!$C$30*NORMSDIST(((LN(Inputs!$C$24/(G$5*Inputs!$C$23))+(Inputs!$C$25+Inputs!$C$29^2/2)*Inputs!$C$22)/(Inputs!$C$29*SQRT(Inputs!$C$22)))-Inputs!$C$29*SQRT(Inputs!$C$22))) -> 37.500627 | H11: =Inputs!$C$11*Inputs!$C$30-Inputs!$C$11/($B11*Inputs!$C$23)*(($B11*Inputs!$C$23)*Inputs!$C$30*NORMSDIST(-(((LN(Inputs!$C$24/($B11*Inputs!$C$23))+(Inputs!$C$25+Inputs!$C$29^2/2)*Inputs!$C$22)/(Inputs!$C$29*SQRT(Inputs!$C$22)))-Inputs!$C$29*SQRT(Inputs!$C$22)))-Inputs!$C$24*NORMSDIST(-((LN(Inputs!$C$24/($B11*Inputs!$C$23))+(Inputs!$C$25+Inputs!$C$29^2/2)*Inputs!$C$22)/(Inputs!$C$29*SQRT(Inputs!$C$22)))))+Inputs!$C$11/(H$5*Inputs!$C$23)*(Inputs!$C$24*NORMSDIST(((LN(Inputs!$C$24/(H$5*Inputs!$C$23))+(Inputs!$C$25+Inputs!$C$29^2/2)*Inputs!$C$22)/(Inputs!$C$29*SQRT(Inputs!$C$22))))-(H$5*Inputs!$C$23)*Inputs!$C$30*NORMSDIST(((LN(Inputs!$C$24/(H$5*Inputs!$C$23))+(Inputs!$C$25+Inputs!$C$29^2/2)*Inputs!$C$22)/(Inputs!$C$29*SQRT(Inputs!$C$22)))-Inputs!$C$29*SQRT(Inputs!$C$22))) -> 37.126299 | I11: =Inputs!$C$11*Inputs!$C$30-Inputs!$C$11/($B11*Inputs!$C$23)*(($B11*Inputs!$C$23)*Inputs!$C$30*NORMSDIST(-(((LN(Inputs!$C$24/($B11*Inputs!$C$23))+(Inputs!$C$25+Inputs!$C$29^2/2)*Inputs!$C$22)/(Inputs!$C$29*SQRT(Inputs!$C$22)))-Inputs!$C$29*SQRT(Inputs!$C$22)))-Inputs!$C$24*NORMSDIST(-((LN(Inputs!$C$24/($B11*Inputs!$C$23))+(Inputs!$C$25+Inputs!$C$29^2/2)*Inputs!$C$22)/(Inputs!$C$29*SQRT(Inputs!$C$22)))))+Inputs!$C$11/(I$5*Inputs!$C$23)*(Inputs!$C$24*NORMSDIST(((LN(Inputs!$C$24/(I$5*Inputs!$C$23))+(Inputs!$C$25+Inputs!$C$29^2/2)*Inputs!$C$22)/(Inputs!$C$29*SQRT(Inputs!$C$22))))-(I$5*Inputs!$C$23)*Inputs!$C$30*NORMSDIST(((LN(Inputs!$C$24/(I$5*Inputs!$C$23))+(Inputs!$C$25+Inputs!$C$29^2/2)*Inputs!$C$22)/(Inputs!$C$29*SQRT(Inputs!$C$22)))-Inputs!$C$29*SQRT(Inputs!$C$22))) -> 36.78802 | J11: =Inputs!$C$11*Inputs!$C$30-Inputs!$C$11/($B11*Inputs!$C$23)*(($B11*Inputs!$C$23)*Inputs!$C$30*NORMSDIST(-(((LN(Inputs!$C$24/($B11*Inputs!$C$23))+(Inputs!$C$25+Inputs!$C$29^2/2)*Inputs!$C$22)/(Inputs!$C$29*SQRT(Inputs!$C$22)))-Inputs!$C$29*SQRT(Inputs!$C$22)))-Inputs!$C$24*NORMSDIST(-((LN(Inputs!$C$24/($B11*Inputs!$C$23))+(Inputs!$C$25+Inputs!$C$29^2/2)*Inputs!$C$22)/(Inputs!$C$29*SQRT(Inputs!$C$22)))))+Inputs!$C$11/(J$5*Inputs!$C$23)*(Inputs!$C$24*NORMSDIST(((LN(Inputs!$C$24/(J$5*Inputs!$C$23))+(Inputs!$C$25+Inputs!$C$29^2/2)*Inputs!$C$22)/(Inputs!$C$29*SQRT(Inputs!$C$22))))-(J$5*Inputs!$C$23)*Inputs!$C$30*NORMSDIST(((LN(Inputs!$C$24/(J$5*Inputs!$C$23))+(Inputs!$C$25+Inputs!$C$29^2/2)*Inputs!$C$22)/(Inputs!$C$29*SQRT(Inputs!$C$22)))-Inputs!$C$29*SQRT(Inputs!$C$22))) -> 36.482559 | ... O11: =Inputs!$C$11*Inputs!$C$30-Inputs!$C$11/($B11*Inputs!$C$23)*(($B11*Inputs!$C$23)*Inputs!$C$30*NORMSDIST(-(((LN(Inputs!$C$24/($B11*Inputs!$C$23))+(Inputs!$C$25+Inputs!$C$29^2/2)*Inputs!$C$22)/(Inputs!$C$29*SQRT(Inputs!$C$22)))-Inputs!$C$29*SQRT(Inputs!$C$22)))-Inputs!$C$24*NORMSDIST(-((LN(Inputs!$C$24/($B11*Inputs!$C$23))+(Inputs!$C$25+Inputs!$C$29^2/2)*Inputs!$C$22)/(Inputs!$C$29*SQRT(Inputs!$C$22)))))+Inputs!$C$11/(O$5*Inputs!$C$23)*(Inputs!$C$24*NORMSDIST(((LN(Inputs!$C$24/(O$5*Inputs!$C$23))+(Inputs!$C$25+Inputs!$C$29^2/2)*Inputs!$C$22)/(Inputs!$C$29*SQRT(Inputs!$C$22))))-(O$5*Inputs!$C$23)*Inputs!$C$30*NORMSDIST(((LN(Inputs!$C$24/(O$5*Inputs!$C$23))+(Inputs!$C$25+Inputs!$C$29^2/2)*Inputs!$C$22)/(Inputs!$C$29*SQRT(Inputs!$C$22)))-Inputs!$C$29*SQRT(Inputs!$C$22))) -> 35.351431
